Traceback (most recent call last):
  File "/home/diggity/wb/OpenNightLights/venv/lib/python3.8/site-packages/nbclient/client.py", line 609, in _async_poll_for_reply
    msg = await ensure_async(self.kc.shell_channel.get_msg(timeout=new_timeout))
  File "/home/diggity/wb/OpenNightLights/venv/lib/python3.8/site-packages/nbclient/util.py", line 85, in ensure_async
    result = await obj
  File "/home/diggity/wb/OpenNightLights/venv/lib/python3.8/site-packages/jupyter_client/asynchronous/channels.py", line 48, in get_msg
    raise Empty
_queue.Empty

During handling of the above exception, another exception occurred:

Traceback (most recent call last):
  File "/home/diggity/wb/OpenNightLights/venv/lib/python3.8/site-packages/jupyter_cache/executors/utils.py", line 51, in single_nb_execution
    executenb(
  File "/home/diggity/wb/OpenNightLights/venv/lib/python3.8/site-packages/nbclient/client.py", line 1087, in execute
    return NotebookClient(nb=nb, resources=resources, km=km, **kwargs).execute()
  File "/home/diggity/wb/OpenNightLights/venv/lib/python3.8/site-packages/nbclient/util.py", line 74, in wrapped
    return just_run(coro(*args, **kwargs))
  File "/home/diggity/wb/OpenNightLights/venv/lib/python3.8/site-packages/nbclient/util.py", line 53, in just_run
    return loop.run_until_complete(coro)
  File "/home/linuxbrew/.linuxbrew/Cellar/python@3.8/3.8.6/lib/python3.8/asyncio/base_events.py", line 616, in run_until_complete
    return future.result()
  File "/home/diggity/wb/OpenNightLights/venv/lib/python3.8/site-packages/nbclient/client.py", line 540, in async_execute
    await self.async_execute_cell(
  File "/home/diggity/wb/OpenNightLights/venv/lib/python3.8/site-packages/nbclient/client.py", line 816, in async_execute_cell
    exec_reply = await self.task_poll_for_reply
  File "/home/diggity/wb/OpenNightLights/venv/lib/python3.8/site-packages/nbclient/client.py", line 633, in _async_poll_for_reply
    await self._async_handle_timeout(timeout, cell)
  File "/home/diggity/wb/OpenNightLights/venv/lib/python3.8/site-packages/nbclient/client.py", line 683, in _async_handle_timeout
    raise CellTimeoutError.error_from_timeout_and_cell(
nbclient.exceptions.CellTimeoutError: A cell timed out while it was being executed, after 30 seconds.
The message was: Cell execution timed out.
Here is a preview of the cell contents:
-------------------
scaleFactor=100

japanSOL = viirsJan2015.reduceRegion(reducer=ee.Reducer.mean(),
                                     geometry=japan0.geometry(),
                                     scale=scaleFactor,
                                     maxPixels=1e9)

print(f"The avg radiance for Japan in Jan 2015 (per {scaleFactor}m grid) is: {japanSOL.get('avg_rad').getInfo():.4f}")
-------------------

