Traceback (most recent call last):
  File "/home/diggity/anaconda3/envs/onl/lib/python3.7/site-packages/nbclient/client.py", line 622, in _async_poll_for_reply
    msg = await ensure_async(self.kc.shell_channel.get_msg(timeout=new_timeout))
  File "/home/diggity/anaconda3/envs/onl/lib/python3.7/site-packages/nbclient/util.py", line 85, in ensure_async
    result = await obj
  File "/home/diggity/anaconda3/envs/onl/lib/python3.7/site-packages/jupyter_client/asynchronous/channels.py", line 48, in get_msg
    raise Empty
_queue.Empty

During handling of the above exception, another exception occurred:

Traceback (most recent call last):
  File "/home/diggity/anaconda3/envs/onl/lib/python3.7/site-packages/jupyter_cache/executors/utils.py", line 56, in single_nb_execution
    record_timing=False,
  File "/home/diggity/anaconda3/envs/onl/lib/python3.7/site-packages/nbclient/client.py", line 1107, in execute
    return NotebookClient(nb=nb, resources=resources, km=km, **kwargs).execute()
  File "/home/diggity/anaconda3/envs/onl/lib/python3.7/site-packages/nbclient/util.py", line 74, in wrapped
    return just_run(coro(*args, **kwargs))
  File "/home/diggity/anaconda3/envs/onl/lib/python3.7/site-packages/nbclient/util.py", line 53, in just_run
    return loop.run_until_complete(coro)
  File "/home/diggity/anaconda3/envs/onl/lib/python3.7/asyncio/base_events.py", line 587, in run_until_complete
    return future.result()
  File "/home/diggity/anaconda3/envs/onl/lib/python3.7/site-packages/nbclient/client.py", line 554, in async_execute
    cell, index, execution_count=self.code_cells_executed + 1
  File "/home/diggity/anaconda3/envs/onl/lib/python3.7/site-packages/nbclient/client.py", line 836, in async_execute_cell
    exec_reply = await self.task_poll_for_reply
  File "/home/diggity/anaconda3/envs/onl/lib/python3.7/site-packages/nbclient/client.py", line 646, in _async_poll_for_reply
    await self._async_handle_timeout(timeout, cell)
  File "/home/diggity/anaconda3/envs/onl/lib/python3.7/site-packages/nbclient/client.py", line 697, in _async_handle_timeout
    "Cell execution timed out", timeout, cell
nbclient.exceptions.CellTimeoutError: A cell timed out while it was being executed, after 30 seconds.
The message was: Cell execution timed out.
Here is a preview of the cell contents:
-------------------
["testResults = test.classify(clf2).errorMatrix(label, 'classification').getInfo()", "testCM = pd.DataFrame(np.asarray(testResults), index=['not','built-up'], columns=['not','built-up'])", '', 'fig, ax = plt.subplots(1, figsize=(10,10))', 'sns.heatmap(testCM/testCM.sum(axis=1), annot=True)']
...
['plt.title("Test data confusion matrix", fontsize=20);', "acc = (testCM.loc['built-up','built-up'] + testCM.loc['not','not']) / testCM.sum().sum()", 'mcc = get_mcc(testCM)', 'print(f"Our classifier has an accuracy of {acc:.5f} on the test data.")', 'print(f"Our classifier has an MCC score of {mcc:.5f} on the test data.")']
-------------------

