Traceback (most recent call last):
  File "/home/diggity/wb/OpenNightLights/venv/lib/python3.8/site-packages/jupyter_cache/executors/utils.py", line 51, in single_nb_execution
    executenb(
  File "/home/diggity/wb/OpenNightLights/venv/lib/python3.8/site-packages/nbclient/client.py", line 1087, in execute
    return NotebookClient(nb=nb, resources=resources, km=km, **kwargs).execute()
  File "/home/diggity/wb/OpenNightLights/venv/lib/python3.8/site-packages/nbclient/util.py", line 74, in wrapped
    return just_run(coro(*args, **kwargs))
  File "/home/diggity/wb/OpenNightLights/venv/lib/python3.8/site-packages/nbclient/util.py", line 53, in just_run
    return loop.run_until_complete(coro)
  File "/home/linuxbrew/.linuxbrew/Cellar/python@3.8/3.8.6/lib/python3.8/asyncio/base_events.py", line 616, in run_until_complete
    return future.result()
  File "/home/diggity/wb/OpenNightLights/venv/lib/python3.8/site-packages/nbclient/client.py", line 540, in async_execute
    await self.async_execute_cell(
  File "/home/diggity/wb/OpenNightLights/venv/lib/python3.8/site-packages/nbclient/client.py", line 832, in async_execute_cell
    self._check_raise_for_error(cell, exec_reply)
  File "/home/diggity/wb/OpenNightLights/venv/lib/python3.8/site-packages/nbclient/client.py", line 740, in _check_raise_for_error
    raise CellExecutionError.from_cell_and_msg(cell, exec_reply['content'])
nbclient.exceptions.CellExecutionError: An error occurred while executing the following cell:
------------------
import geopandas as gpd
------------------

[0;31m---------------------------------------------------------------------------[0m
[0;31mModuleNotFoundError[0m                       Traceback (most recent call last)
[0;32m<ipython-input-1-a62d01c1d62e>[0m in [0;36m<module>[0;34m[0m
[0;32m----> 1[0;31m [0;32mimport[0m [0mgeopandas[0m [0;32mas[0m [0mgpd[0m[0;34m[0m[0;34m[0m[0m
[0m
[0;31mModuleNotFoundError[0m: No module named 'geopandas'
ModuleNotFoundError: No module named 'geopandas'

